2024-08-25 11:23:27,543 - model_training - ERROR - Error comparing models: API request to https://dagshub.com/datascience-1100/End-to-End-Employee-Attrition-Rate-Project.mlflow/api/2.0/mlflow/runs/create failed with exception HTTPSConnectionPool(host='dagshub.com', port=443): Max retries exceeded with url: /datascience-1100/End-to-End-Employee-Attrition-Rate-Project.mlflow/api/2.0/mlflow/runs/create (Caused by ResponseError('too many 500 error responses'))
2024-08-25 11:23:27,546 - model_training - ERROR - An error occurred during the model training process: API request to https://dagshub.com/datascience-1100/End-to-End-Employee-Attrition-Rate-Project.mlflow/api/2.0/mlflow/runs/create failed with exception HTTPSConnectionPool(host='dagshub.com', port=443): Max retries exceeded with url: /datascience-1100/End-to-End-Employee-Attrition-Rate-Project.mlflow/api/2.0/mlflow/runs/create (Caused by ResponseError('too many 500 error responses'))
2024-08-25 11:26:01,512 - model_training - ERROR - Error comparing models: API request to https://dagshub.com/datascience-1100/End-to-End-Employee-Attrition-Rate-Project.mlflow/api/2.0/mlflow/runs/create failed with exception HTTPSConnectionPool(host='dagshub.com', port=443): Max retries exceeded with url: /datascience-1100/End-to-End-Employee-Attrition-Rate-Project.mlflow/api/2.0/mlflow/runs/create (Caused by ResponseError('too many 500 error responses'))
2024-08-25 11:26:01,513 - model_training - ERROR - An error occurred during the model training process: API request to https://dagshub.com/datascience-1100/End-to-End-Employee-Attrition-Rate-Project.mlflow/api/2.0/mlflow/runs/create failed with exception HTTPSConnectionPool(host='dagshub.com', port=443): Max retries exceeded with url: /datascience-1100/End-to-End-Employee-Attrition-Rate-Project.mlflow/api/2.0/mlflow/runs/create (Caused by ResponseError('too many 500 error responses'))
2024-08-25 11:28:25,399 - model_training - ERROR - Error comparing models: API request to https://dagshub.com/datascience-1100/End-to-End-Employee-Attrition-Rate-Project.mlflow/api/2.0/mlflow/runs/create failed with exception HTTPSConnectionPool(host='dagshub.com', port=443): Max retries exceeded with url: /datascience-1100/End-to-End-Employee-Attrition-Rate-Project.mlflow/api/2.0/mlflow/runs/create (Caused by ResponseError('too many 500 error responses'))
2024-08-25 11:28:25,400 - model_training - ERROR - An error occurred during the model training process: API request to https://dagshub.com/datascience-1100/End-to-End-Employee-Attrition-Rate-Project.mlflow/api/2.0/mlflow/runs/create failed with exception HTTPSConnectionPool(host='dagshub.com', port=443): Max retries exceeded with url: /datascience-1100/End-to-End-Employee-Attrition-Rate-Project.mlflow/api/2.0/mlflow/runs/create (Caused by ResponseError('too many 500 error responses'))
2024-08-25 11:30:19,879 - model_training - ERROR - Error comparing models: API request to https://dagshub.com/datascience-1100/End-to-End-Employee-Attrition-Rate-Project.mlflow/api/2.0/mlflow/runs/create failed with exception HTTPSConnectionPool(host='dagshub.com', port=443): Max retries exceeded with url: /datascience-1100/End-to-End-Employee-Attrition-Rate-Project.mlflow/api/2.0/mlflow/runs/create (Caused by ResponseError('too many 500 error responses'))
2024-08-25 11:30:19,881 - model_training - ERROR - An error occurred during the model training process: API request to https://dagshub.com/datascience-1100/End-to-End-Employee-Attrition-Rate-Project.mlflow/api/2.0/mlflow/runs/create failed with exception HTTPSConnectionPool(host='dagshub.com', port=443): Max retries exceeded with url: /datascience-1100/End-to-End-Employee-Attrition-Rate-Project.mlflow/api/2.0/mlflow/runs/create (Caused by ResponseError('too many 500 error responses'))
2024-08-25 11:37:18,388 - model_training - ERROR - Error comparing models: 
All the 5 fits failed.
It is very likely that your model is misconfigured.
You can try to debug the error by setting error_score='raise'.

Below are more details about the failures:
--------------------------------------------------------------------------------
5 fits failed with the following error:
Traceback (most recent call last):
  File "C:\Users\Subha\OneDrive\Desktop\Emp Attrition Rate Project\myenv\lib\site-packages\sklearn\model_selection\_validation.py", line 732, in _fit_and_score
    estimator.fit(X_train, y_train, **fit_params)
  File "C:\Users\Subha\OneDrive\Desktop\Emp Attrition Rate Project\myenv\lib\site-packages\sklearn\base.py", line 1151, in wrapper
    return fit_method(estimator, *args, **kwargs)
  File "C:\Users\Subha\OneDrive\Desktop\Emp Attrition Rate Project\myenv\lib\site-packages\sklearn\model_selection\_search.py", line 898, in fit
    self._run_search(evaluate_candidates)
  File "C:\Users\Subha\OneDrive\Desktop\Emp Attrition Rate Project\myenv\lib\site-packages\sklearn\model_selection\_search.py", line 1419, in _run_search
    evaluate_candidates(ParameterGrid(self.param_grid))
  File "C:\Users\Subha\OneDrive\Desktop\Emp Attrition Rate Project\myenv\lib\site-packages\sklearn\model_selection\_search.py", line 875, in evaluate_candidates
    _warn_or_raise_about_fit_failures(out, self.error_score)
  File "C:\Users\Subha\OneDrive\Desktop\Emp Attrition Rate Project\myenv\lib\site-packages\sklearn\model_selection\_validation.py", line 414, in _warn_or_raise_about_fit_failures
    raise ValueError(all_fits_failed_message)
ValueError: 
All the 5 fits failed.
It is very likely that your model is misconfigured.
You can try to debug the error by setting error_score='raise'.

Below are more details about the failures:
--------------------------------------------------------------------------------
5 fits failed with the following error:
Traceback (most recent call last):
  File "C:\Users\Subha\OneDrive\Desktop\Emp Attrition Rate Project\myenv\lib\site-packages\sklearn\model_selection\_validation.py", line 732, in _fit_and_score
    estimator.fit(X_train, y_train, **fit_params)
  File "C:\Users\Subha\OneDrive\Desktop\Emp Attrition Rate Project\myenv\lib\site-packages\sklearn\base.py", line 1144, in wrapper
    estimator._validate_params()
  File "C:\Users\Subha\OneDrive\Desktop\Emp Attrition Rate Project\myenv\lib\site-packages\sklearn\base.py", line 637, in _validate_params
    validate_parameter_constraints(
  File "C:\Users\Subha\OneDrive\Desktop\Emp Attrition Rate Project\myenv\lib\site-packages\sklearn\utils\_param_validation.py", line 95, in validate_parameter_constraints
    raise InvalidParameterError(
sklearn.utils._param_validation.InvalidParameterError: The 'max_depth' parameter of DecisionTreeClassifier must be an int in the range [1, inf) or None. Got [3, 5, 7] instead.


2024-08-25 11:37:18,394 - model_training - ERROR - An error occurred during the model training process: 
All the 5 fits failed.
It is very likely that your model is misconfigured.
You can try to debug the error by setting error_score='raise'.

Below are more details about the failures:
--------------------------------------------------------------------------------
5 fits failed with the following error:
Traceback (most recent call last):
  File "C:\Users\Subha\OneDrive\Desktop\Emp Attrition Rate Project\myenv\lib\site-packages\sklearn\model_selection\_validation.py", line 732, in _fit_and_score
    estimator.fit(X_train, y_train, **fit_params)
  File "C:\Users\Subha\OneDrive\Desktop\Emp Attrition Rate Project\myenv\lib\site-packages\sklearn\base.py", line 1151, in wrapper
    return fit_method(estimator, *args, **kwargs)
  File "C:\Users\Subha\OneDrive\Desktop\Emp Attrition Rate Project\myenv\lib\site-packages\sklearn\model_selection\_search.py", line 898, in fit
    self._run_search(evaluate_candidates)
  File "C:\Users\Subha\OneDrive\Desktop\Emp Attrition Rate Project\myenv\lib\site-packages\sklearn\model_selection\_search.py", line 1419, in _run_search
    evaluate_candidates(ParameterGrid(self.param_grid))
  File "C:\Users\Subha\OneDrive\Desktop\Emp Attrition Rate Project\myenv\lib\site-packages\sklearn\model_selection\_search.py", line 875, in evaluate_candidates
    _warn_or_raise_about_fit_failures(out, self.error_score)
  File "C:\Users\Subha\OneDrive\Desktop\Emp Attrition Rate Project\myenv\lib\site-packages\sklearn\model_selection\_validation.py", line 414, in _warn_or_raise_about_fit_failures
    raise ValueError(all_fits_failed_message)
ValueError: 
All the 5 fits failed.
It is very likely that your model is misconfigured.
You can try to debug the error by setting error_score='raise'.

Below are more details about the failures:
--------------------------------------------------------------------------------
5 fits failed with the following error:
Traceback (most recent call last):
  File "C:\Users\Subha\OneDrive\Desktop\Emp Attrition Rate Project\myenv\lib\site-packages\sklearn\model_selection\_validation.py", line 732, in _fit_and_score
    estimator.fit(X_train, y_train, **fit_params)
  File "C:\Users\Subha\OneDrive\Desktop\Emp Attrition Rate Project\myenv\lib\site-packages\sklearn\base.py", line 1144, in wrapper
    estimator._validate_params()
  File "C:\Users\Subha\OneDrive\Desktop\Emp Attrition Rate Project\myenv\lib\site-packages\sklearn\base.py", line 637, in _validate_params
    validate_parameter_constraints(
  File "C:\Users\Subha\OneDrive\Desktop\Emp Attrition Rate Project\myenv\lib\site-packages\sklearn\utils\_param_validation.py", line 95, in validate_parameter_constraints
    raise InvalidParameterError(
sklearn.utils._param_validation.InvalidParameterError: The 'max_depth' parameter of DecisionTreeClassifier must be an int in the range [1, inf) or None. Got [3, 5, 7] instead.


2024-08-25 11:52:20,135 - model_training - ERROR - Error comparing models: 
All the 5 fits failed.
It is very likely that your model is misconfigured.
You can try to debug the error by setting error_score='raise'.

Below are more details about the failures:
--------------------------------------------------------------------------------
5 fits failed with the following error:
Traceback (most recent call last):
  File "C:\Users\Subha\OneDrive\Desktop\Emp Attrition Rate Project\myenv\lib\site-packages\sklearn\model_selection\_validation.py", line 732, in _fit_and_score
    estimator.fit(X_train, y_train, **fit_params)
  File "C:\Users\Subha\OneDrive\Desktop\Emp Attrition Rate Project\myenv\lib\site-packages\sklearn\base.py", line 1151, in wrapper
    return fit_method(estimator, *args, **kwargs)
  File "C:\Users\Subha\OneDrive\Desktop\Emp Attrition Rate Project\myenv\lib\site-packages\sklearn\model_selection\_search.py", line 898, in fit
    self._run_search(evaluate_candidates)
  File "C:\Users\Subha\OneDrive\Desktop\Emp Attrition Rate Project\myenv\lib\site-packages\sklearn\model_selection\_search.py", line 1419, in _run_search
    evaluate_candidates(ParameterGrid(self.param_grid))
  File "C:\Users\Subha\OneDrive\Desktop\Emp Attrition Rate Project\myenv\lib\site-packages\sklearn\model_selection\_search.py", line 875, in evaluate_candidates
    _warn_or_raise_about_fit_failures(out, self.error_score)
  File "C:\Users\Subha\OneDrive\Desktop\Emp Attrition Rate Project\myenv\lib\site-packages\sklearn\model_selection\_validation.py", line 414, in _warn_or_raise_about_fit_failures
    raise ValueError(all_fits_failed_message)
ValueError: 
All the 5 fits failed.
It is very likely that your model is misconfigured.
You can try to debug the error by setting error_score='raise'.

Below are more details about the failures:
--------------------------------------------------------------------------------
5 fits failed with the following error:
Traceback (most recent call last):
  File "C:\Users\Subha\OneDrive\Desktop\Emp Attrition Rate Project\myenv\lib\site-packages\sklearn\model_selection\_validation.py", line 732, in _fit_and_score
    estimator.fit(X_train, y_train, **fit_params)
  File "C:\Users\Subha\OneDrive\Desktop\Emp Attrition Rate Project\myenv\lib\site-packages\sklearn\base.py", line 1144, in wrapper
    estimator._validate_params()
  File "C:\Users\Subha\OneDrive\Desktop\Emp Attrition Rate Project\myenv\lib\site-packages\sklearn\base.py", line 637, in _validate_params
    validate_parameter_constraints(
  File "C:\Users\Subha\OneDrive\Desktop\Emp Attrition Rate Project\myenv\lib\site-packages\sklearn\utils\_param_validation.py", line 95, in validate_parameter_constraints
    raise InvalidParameterError(
sklearn.utils._param_validation.InvalidParameterError: The 'max_depth' parameter of DecisionTreeClassifier must be an int in the range [1, inf) or None. Got [3, 5, 7] instead.


2024-08-25 11:52:20,143 - model_training - ERROR - An error occurred during the model training process: 
All the 5 fits failed.
It is very likely that your model is misconfigured.
You can try to debug the error by setting error_score='raise'.

Below are more details about the failures:
--------------------------------------------------------------------------------
5 fits failed with the following error:
Traceback (most recent call last):
  File "C:\Users\Subha\OneDrive\Desktop\Emp Attrition Rate Project\myenv\lib\site-packages\sklearn\model_selection\_validation.py", line 732, in _fit_and_score
    estimator.fit(X_train, y_train, **fit_params)
  File "C:\Users\Subha\OneDrive\Desktop\Emp Attrition Rate Project\myenv\lib\site-packages\sklearn\base.py", line 1151, in wrapper
    return fit_method(estimator, *args, **kwargs)
  File "C:\Users\Subha\OneDrive\Desktop\Emp Attrition Rate Project\myenv\lib\site-packages\sklearn\model_selection\_search.py", line 898, in fit
    self._run_search(evaluate_candidates)
  File "C:\Users\Subha\OneDrive\Desktop\Emp Attrition Rate Project\myenv\lib\site-packages\sklearn\model_selection\_search.py", line 1419, in _run_search
    evaluate_candidates(ParameterGrid(self.param_grid))
  File "C:\Users\Subha\OneDrive\Desktop\Emp Attrition Rate Project\myenv\lib\site-packages\sklearn\model_selection\_search.py", line 875, in evaluate_candidates
    _warn_or_raise_about_fit_failures(out, self.error_score)
  File "C:\Users\Subha\OneDrive\Desktop\Emp Attrition Rate Project\myenv\lib\site-packages\sklearn\model_selection\_validation.py", line 414, in _warn_or_raise_about_fit_failures
    raise ValueError(all_fits_failed_message)
ValueError: 
All the 5 fits failed.
It is very likely that your model is misconfigured.
You can try to debug the error by setting error_score='raise'.

Below are more details about the failures:
--------------------------------------------------------------------------------
5 fits failed with the following error:
Traceback (most recent call last):
  File "C:\Users\Subha\OneDrive\Desktop\Emp Attrition Rate Project\myenv\lib\site-packages\sklearn\model_selection\_validation.py", line 732, in _fit_and_score
    estimator.fit(X_train, y_train, **fit_params)
  File "C:\Users\Subha\OneDrive\Desktop\Emp Attrition Rate Project\myenv\lib\site-packages\sklearn\base.py", line 1144, in wrapper
    estimator._validate_params()
  File "C:\Users\Subha\OneDrive\Desktop\Emp Attrition Rate Project\myenv\lib\site-packages\sklearn\base.py", line 637, in _validate_params
    validate_parameter_constraints(
  File "C:\Users\Subha\OneDrive\Desktop\Emp Attrition Rate Project\myenv\lib\site-packages\sklearn\utils\_param_validation.py", line 95, in validate_parameter_constraints
    raise InvalidParameterError(
sklearn.utils._param_validation.InvalidParameterError: The 'max_depth' parameter of DecisionTreeClassifier must be an int in the range [1, inf) or None. Got [3, 5, 7] instead.


2024-08-25 11:53:05,703 - model_training - ERROR - Error comparing models: 
All the 5 fits failed.
It is very likely that your model is misconfigured.
You can try to debug the error by setting error_score='raise'.

Below are more details about the failures:
--------------------------------------------------------------------------------
5 fits failed with the following error:
Traceback (most recent call last):
  File "C:\Users\Subha\OneDrive\Desktop\Emp Attrition Rate Project\myenv\lib\site-packages\sklearn\model_selection\_validation.py", line 732, in _fit_and_score
    estimator.fit(X_train, y_train, **fit_params)
  File "C:\Users\Subha\OneDrive\Desktop\Emp Attrition Rate Project\myenv\lib\site-packages\sklearn\base.py", line 1151, in wrapper
    return fit_method(estimator, *args, **kwargs)
  File "C:\Users\Subha\OneDrive\Desktop\Emp Attrition Rate Project\myenv\lib\site-packages\sklearn\model_selection\_search.py", line 898, in fit
    self._run_search(evaluate_candidates)
  File "C:\Users\Subha\OneDrive\Desktop\Emp Attrition Rate Project\myenv\lib\site-packages\sklearn\model_selection\_search.py", line 1419, in _run_search
    evaluate_candidates(ParameterGrid(self.param_grid))
  File "C:\Users\Subha\OneDrive\Desktop\Emp Attrition Rate Project\myenv\lib\site-packages\sklearn\model_selection\_search.py", line 875, in evaluate_candidates
    _warn_or_raise_about_fit_failures(out, self.error_score)
  File "C:\Users\Subha\OneDrive\Desktop\Emp Attrition Rate Project\myenv\lib\site-packages\sklearn\model_selection\_validation.py", line 414, in _warn_or_raise_about_fit_failures
    raise ValueError(all_fits_failed_message)
ValueError: 
All the 5 fits failed.
It is very likely that your model is misconfigured.
You can try to debug the error by setting error_score='raise'.

Below are more details about the failures:
--------------------------------------------------------------------------------
5 fits failed with the following error:
Traceback (most recent call last):
  File "C:\Users\Subha\OneDrive\Desktop\Emp Attrition Rate Project\myenv\lib\site-packages\sklearn\model_selection\_validation.py", line 732, in _fit_and_score
    estimator.fit(X_train, y_train, **fit_params)
  File "C:\Users\Subha\OneDrive\Desktop\Emp Attrition Rate Project\myenv\lib\site-packages\xgboost\core.py", line 726, in inner_f
    return func(**kwargs)
  File "C:\Users\Subha\OneDrive\Desktop\Emp Attrition Rate Project\myenv\lib\site-packages\xgboost\sklearn.py", line 1531, in fit
    self._Booster = train(
  File "C:\Users\Subha\OneDrive\Desktop\Emp Attrition Rate Project\myenv\lib\site-packages\xgboost\core.py", line 726, in inner_f
    return func(**kwargs)
  File "C:\Users\Subha\OneDrive\Desktop\Emp Attrition Rate Project\myenv\lib\site-packages\xgboost\training.py", line 181, in train
    bst.update(dtrain, iteration=i, fobj=obj)
  File "C:\Users\Subha\OneDrive\Desktop\Emp Attrition Rate Project\myenv\lib\site-packages\xgboost\core.py", line 2100, in update
    _check_call(
  File "C:\Users\Subha\OneDrive\Desktop\Emp Attrition Rate Project\myenv\lib\site-packages\xgboost\core.py", line 284, in _check_call
    raise XGBoostError(py_str(_LIB.XGBGetLastError()))
xgboost.core.XGBoostError: Invalid Parameter format for learning_rate expect float but value='[0.1, 0.2]'


2024-08-25 11:53:05,711 - model_training - ERROR - An error occurred during the model training process: 
All the 5 fits failed.
It is very likely that your model is misconfigured.
You can try to debug the error by setting error_score='raise'.

Below are more details about the failures:
--------------------------------------------------------------------------------
5 fits failed with the following error:
Traceback (most recent call last):
  File "C:\Users\Subha\OneDrive\Desktop\Emp Attrition Rate Project\myenv\lib\site-packages\sklearn\model_selection\_validation.py", line 732, in _fit_and_score
    estimator.fit(X_train, y_train, **fit_params)
  File "C:\Users\Subha\OneDrive\Desktop\Emp Attrition Rate Project\myenv\lib\site-packages\sklearn\base.py", line 1151, in wrapper
    return fit_method(estimator, *args, **kwargs)
  File "C:\Users\Subha\OneDrive\Desktop\Emp Attrition Rate Project\myenv\lib\site-packages\sklearn\model_selection\_search.py", line 898, in fit
    self._run_search(evaluate_candidates)
  File "C:\Users\Subha\OneDrive\Desktop\Emp Attrition Rate Project\myenv\lib\site-packages\sklearn\model_selection\_search.py", line 1419, in _run_search
    evaluate_candidates(ParameterGrid(self.param_grid))
  File "C:\Users\Subha\OneDrive\Desktop\Emp Attrition Rate Project\myenv\lib\site-packages\sklearn\model_selection\_search.py", line 875, in evaluate_candidates
    _warn_or_raise_about_fit_failures(out, self.error_score)
  File "C:\Users\Subha\OneDrive\Desktop\Emp Attrition Rate Project\myenv\lib\site-packages\sklearn\model_selection\_validation.py", line 414, in _warn_or_raise_about_fit_failures
    raise ValueError(all_fits_failed_message)
ValueError: 
All the 5 fits failed.
It is very likely that your model is misconfigured.
You can try to debug the error by setting error_score='raise'.

Below are more details about the failures:
--------------------------------------------------------------------------------
5 fits failed with the following error:
Traceback (most recent call last):
  File "C:\Users\Subha\OneDrive\Desktop\Emp Attrition Rate Project\myenv\lib\site-packages\sklearn\model_selection\_validation.py", line 732, in _fit_and_score
    estimator.fit(X_train, y_train, **fit_params)
  File "C:\Users\Subha\OneDrive\Desktop\Emp Attrition Rate Project\myenv\lib\site-packages\xgboost\core.py", line 726, in inner_f
    return func(**kwargs)
  File "C:\Users\Subha\OneDrive\Desktop\Emp Attrition Rate Project\myenv\lib\site-packages\xgboost\sklearn.py", line 1531, in fit
    self._Booster = train(
  File "C:\Users\Subha\OneDrive\Desktop\Emp Attrition Rate Project\myenv\lib\site-packages\xgboost\core.py", line 726, in inner_f
    return func(**kwargs)
  File "C:\Users\Subha\OneDrive\Desktop\Emp Attrition Rate Project\myenv\lib\site-packages\xgboost\training.py", line 181, in train
    bst.update(dtrain, iteration=i, fobj=obj)
  File "C:\Users\Subha\OneDrive\Desktop\Emp Attrition Rate Project\myenv\lib\site-packages\xgboost\core.py", line 2100, in update
    _check_call(
  File "C:\Users\Subha\OneDrive\Desktop\Emp Attrition Rate Project\myenv\lib\site-packages\xgboost\core.py", line 284, in _check_call
    raise XGBoostError(py_str(_LIB.XGBGetLastError()))
xgboost.core.XGBoostError: Invalid Parameter format for learning_rate expect float but value='[0.1, 0.2]'


2024-08-25 13:21:47,188 - model_training - ERROR - Error comparing models: 
All the 5 fits failed.
It is very likely that your model is misconfigured.
You can try to debug the error by setting error_score='raise'.

Below are more details about the failures:
--------------------------------------------------------------------------------
5 fits failed with the following error:
Traceback (most recent call last):
  File "C:\Users\Subha\OneDrive\Desktop\Emp Attrition Rate Project\myenv\lib\site-packages\sklearn\model_selection\_validation.py", line 732, in _fit_and_score
    estimator.fit(X_train, y_train, **fit_params)
  File "C:\Users\Subha\OneDrive\Desktop\Emp Attrition Rate Project\myenv\lib\site-packages\mlflow\utils\autologging_utils\safety.py", line 580, in safe_patch_function
    patch_function(call_original, *args, **kwargs)
  File "C:\Users\Subha\OneDrive\Desktop\Emp Attrition Rate Project\myenv\lib\site-packages\mlflow\utils\autologging_utils\safety.py", line 249, in patch_with_managed_run
    result = patch_function(original, *args, **kwargs)
  File "C:\Users\Subha\OneDrive\Desktop\Emp Attrition Rate Project\myenv\lib\site-packages\mlflow\sklearn\__init__.py", line 1653, in patched_fit
    result = fit_impl(original, self, *args, **kwargs)
  File "C:\Users\Subha\OneDrive\Desktop\Emp Attrition Rate Project\myenv\lib\site-packages\mlflow\sklearn\__init__.py", line 1428, in fit_mlflow
    fit_output = original(self, *args, **kwargs)
  File "C:\Users\Subha\OneDrive\Desktop\Emp Attrition Rate Project\myenv\lib\site-packages\mlflow\utils\autologging_utils\safety.py", line 561, in call_original
    return call_original_fn_with_event_logging(_original_fn, og_args, og_kwargs)
  File "C:\Users\Subha\OneDrive\Desktop\Emp Attrition Rate Project\myenv\lib\site-packages\mlflow\utils\autologging_utils\safety.py", line 496, in call_original_fn_with_event_logging
    original_fn_result = original_fn(*og_args, **og_kwargs)
  File "C:\Users\Subha\OneDrive\Desktop\Emp Attrition Rate Project\myenv\lib\site-packages\mlflow\utils\autologging_utils\safety.py", line 558, in _original_fn
    original_result = original(*_og_args, **_og_kwargs)
  File "C:\Users\Subha\OneDrive\Desktop\Emp Attrition Rate Project\myenv\lib\site-packages\sklearn\base.py", line 1151, in wrapper
    return fit_method(estimator, *args, **kwargs)
  File "C:\Users\Subha\OneDrive\Desktop\Emp Attrition Rate Project\myenv\lib\site-packages\sklearn\model_selection\_search.py", line 898, in fit
    self._run_search(evaluate_candidates)
  File "C:\Users\Subha\OneDrive\Desktop\Emp Attrition Rate Project\myenv\lib\site-packages\sklearn\model_selection\_search.py", line 1419, in _run_search
    evaluate_candidates(ParameterGrid(self.param_grid))
  File "C:\Users\Subha\OneDrive\Desktop\Emp Attrition Rate Project\myenv\lib\site-packages\sklearn\model_selection\_search.py", line 875, in evaluate_candidates
    _warn_or_raise_about_fit_failures(out, self.error_score)
  File "C:\Users\Subha\OneDrive\Desktop\Emp Attrition Rate Project\myenv\lib\site-packages\sklearn\model_selection\_validation.py", line 414, in _warn_or_raise_about_fit_failures
    raise ValueError(all_fits_failed_message)
ValueError: 
All the 5 fits failed.
It is very likely that your model is misconfigured.
You can try to debug the error by setting error_score='raise'.

Below are more details about the failures:
--------------------------------------------------------------------------------
5 fits failed with the following error:
Traceback (most recent call last):
  File "C:\Users\Subha\OneDrive\Desktop\Emp Attrition Rate Project\myenv\lib\site-packages\sklearn\model_selection\_validation.py", line 732, in _fit_and_score
    estimator.fit(X_train, y_train, **fit_params)
  File "C:\Users\Subha\OneDrive\Desktop\Emp Attrition Rate Project\myenv\lib\site-packages\sklearn\base.py", line 1144, in wrapper
    estimator._validate_params()
  File "C:\Users\Subha\OneDrive\Desktop\Emp Attrition Rate Project\myenv\lib\site-packages\sklearn\base.py", line 637, in _validate_params
    validate_parameter_constraints(
  File "C:\Users\Subha\OneDrive\Desktop\Emp Attrition Rate Project\myenv\lib\site-packages\sklearn\utils\_param_validation.py", line 95, in validate_parameter_constraints
    raise InvalidParameterError(
sklearn.utils._param_validation.InvalidParameterError: The 'max_depth' parameter of DecisionTreeClassifier must be an int in the range [1, inf) or None. Got [5, 7] instead.


2024-08-25 13:21:47,196 - model_training - ERROR - An error occurred during the model training process: 
All the 5 fits failed.
It is very likely that your model is misconfigured.
You can try to debug the error by setting error_score='raise'.

Below are more details about the failures:
--------------------------------------------------------------------------------
5 fits failed with the following error:
Traceback (most recent call last):
  File "C:\Users\Subha\OneDrive\Desktop\Emp Attrition Rate Project\myenv\lib\site-packages\sklearn\model_selection\_validation.py", line 732, in _fit_and_score
    estimator.fit(X_train, y_train, **fit_params)
  File "C:\Users\Subha\OneDrive\Desktop\Emp Attrition Rate Project\myenv\lib\site-packages\mlflow\utils\autologging_utils\safety.py", line 580, in safe_patch_function
    patch_function(call_original, *args, **kwargs)
  File "C:\Users\Subha\OneDrive\Desktop\Emp Attrition Rate Project\myenv\lib\site-packages\mlflow\utils\autologging_utils\safety.py", line 249, in patch_with_managed_run
    result = patch_function(original, *args, **kwargs)
  File "C:\Users\Subha\OneDrive\Desktop\Emp Attrition Rate Project\myenv\lib\site-packages\mlflow\sklearn\__init__.py", line 1653, in patched_fit
    result = fit_impl(original, self, *args, **kwargs)
  File "C:\Users\Subha\OneDrive\Desktop\Emp Attrition Rate Project\myenv\lib\site-packages\mlflow\sklearn\__init__.py", line 1428, in fit_mlflow
    fit_output = original(self, *args, **kwargs)
  File "C:\Users\Subha\OneDrive\Desktop\Emp Attrition Rate Project\myenv\lib\site-packages\mlflow\utils\autologging_utils\safety.py", line 561, in call_original
    return call_original_fn_with_event_logging(_original_fn, og_args, og_kwargs)
  File "C:\Users\Subha\OneDrive\Desktop\Emp Attrition Rate Project\myenv\lib\site-packages\mlflow\utils\autologging_utils\safety.py", line 496, in call_original_fn_with_event_logging
    original_fn_result = original_fn(*og_args, **og_kwargs)
  File "C:\Users\Subha\OneDrive\Desktop\Emp Attrition Rate Project\myenv\lib\site-packages\mlflow\utils\autologging_utils\safety.py", line 558, in _original_fn
    original_result = original(*_og_args, **_og_kwargs)
  File "C:\Users\Subha\OneDrive\Desktop\Emp Attrition Rate Project\myenv\lib\site-packages\sklearn\base.py", line 1151, in wrapper
    return fit_method(estimator, *args, **kwargs)
  File "C:\Users\Subha\OneDrive\Desktop\Emp Attrition Rate Project\myenv\lib\site-packages\sklearn\model_selection\_search.py", line 898, in fit
    self._run_search(evaluate_candidates)
  File "C:\Users\Subha\OneDrive\Desktop\Emp Attrition Rate Project\myenv\lib\site-packages\sklearn\model_selection\_search.py", line 1419, in _run_search
    evaluate_candidates(ParameterGrid(self.param_grid))
  File "C:\Users\Subha\OneDrive\Desktop\Emp Attrition Rate Project\myenv\lib\site-packages\sklearn\model_selection\_search.py", line 875, in evaluate_candidates
    _warn_or_raise_about_fit_failures(out, self.error_score)
  File "C:\Users\Subha\OneDrive\Desktop\Emp Attrition Rate Project\myenv\lib\site-packages\sklearn\model_selection\_validation.py", line 414, in _warn_or_raise_about_fit_failures
    raise ValueError(all_fits_failed_message)
ValueError: 
All the 5 fits failed.
It is very likely that your model is misconfigured.
You can try to debug the error by setting error_score='raise'.

Below are more details about the failures:
--------------------------------------------------------------------------------
5 fits failed with the following error:
Traceback (most recent call last):
  File "C:\Users\Subha\OneDrive\Desktop\Emp Attrition Rate Project\myenv\lib\site-packages\sklearn\model_selection\_validation.py", line 732, in _fit_and_score
    estimator.fit(X_train, y_train, **fit_params)
  File "C:\Users\Subha\OneDrive\Desktop\Emp Attrition Rate Project\myenv\lib\site-packages\sklearn\base.py", line 1144, in wrapper
    estimator._validate_params()
  File "C:\Users\Subha\OneDrive\Desktop\Emp Attrition Rate Project\myenv\lib\site-packages\sklearn\base.py", line 637, in _validate_params
    validate_parameter_constraints(
  File "C:\Users\Subha\OneDrive\Desktop\Emp Attrition Rate Project\myenv\lib\site-packages\sklearn\utils\_param_validation.py", line 95, in validate_parameter_constraints
    raise InvalidParameterError(
sklearn.utils._param_validation.InvalidParameterError: The 'max_depth' parameter of DecisionTreeClassifier must be an int in the range [1, inf) or None. Got [5, 7] instead.


